Workbook

Sheet Appointments
A1: appointment_id | B1: patient_id | C1: doctor_id | D1: appointment_date | E1: booking_date | F1: department | G1: status | H1: waiting_days | I1: appointment_time
A2: A00001 | B2: P0589 | C2: D014 | D2: 45913 | E2: 45877 | F2: Dermatology | G2: Attended | H2: 36 | I2: 09:00
A3: A00002 | B3: P0572 | C3: D025 | D3: 45746 | E3: 45707 | F3: Orthopedics | G3: Attended | H3: 39 | I3: 14:00
A4: A00003 | B4: P0501 | C4: D023 | D4: 45809 | E4: 45784 | F4: Pediatrics | G4: No-show | H4: 25 | I4: 09:00
A5: A00004 | B5: P0070 | C5: D011 | D5: 45921 | E5: 45919 | F5: ENT | G5: No-show | H5: 2 | I5: 09:00
A6: A00005 | B6: P0319 | C6: D008 | D6: 46007 | E6: 45952 | F6: General Medicine | G6: Attended | H6: 55 | I6: 13:30
A7: A00006 | B7: P0315 | C7: D028 | D7: 45867 | E7: 45855 | F7: Pediatrics | G7: Attended | H7: 12 | I7: 10:30
A8: A00007 | B8: P0415 | C8: D016 | D8: 45756 | E8: 45697 | F8: Cardiology | G8: Attended | H8: 59 | I8: 08:30
A9: A00008 | B9: P0550 | C9: D004 | D9: 45912 | E9: 45856 | F9: Ophthalmology | G9: No-show | H9: 56 | I9: 16:00
A10: A00009 | B10: P0209 | C10: D007 | D10: 45908 | E10: 45907 | F10: Orthopedics | G10: No-show | H10: 1 | I10: 16:00
A11: A00010 | B11: P0363 | C11: D024 | D11: 45893 | E11: 45848 | F11: Neurology | G11: Cancelled | H11: 45 | I11: 13:30
A12: A00011 | B12: P0172 | C12: D026 | D12: 45674 | E12: 45636 | F12: General Medicine | G12: No-show | H12: 38 | I12: 13:30
A13: A00012 | B13: P0137 | C13: D026 | D13: 45915 | E13: 45901 | F13: General Medicine | G13: No-show | H13: 14 | I13: 15:30
... A217: A00216 | B217: P0116 | C217: D026 | D217: 45927 | E217: 45904 | F217: General Medicine | G217: No-show | H217: 23 | I217: 09:00
A218: A00217 | B218: P0335 | C218: D003 | D218: 45753 | E218: 45753 | F218: Orthopedics | H218: 0 | I218: 14:00
A219: A00218 | B219: P0234 | C219: D018 | D219: 45981 | E219: 45949 | F219: Neurology | G219: Attended | H219: 32 | I219: 14:00
A220: A00219 | B220: P0462 | C220: D022 | D220: 45738 | E220: 45727 | F220: Pediatrics | H220: 11 | I220: 09:00
A221: A00220 | B221: P0261 | C221: D001 | D221: 45996 | E221: 45996 | F221: ENT | G221: Attended | H221: 0 | I221: 13:30
A222: A00221 | B222: P0648 | C222: D017 | D222: 45699 | E222: 45692 | F222: ENT | G222: Cancelled | H222: 7 | I222: 14:00
A223: A00222 | B223: P0195 | C223: D026 | D223: 45898 | E223: 45881 | F223: General Medicine | G223: Attended | H223: 17 | I223: 09:00
A224: A00223 | B224: P0235 | C224: D008 | D224: 45664 | E224: 45633 | F224: General Medicine | G224: Attended | H224: 31 | I224: 11:00
A225: A00224 | B225: P0003 | C225: D025 | D225: 45730 | E225: 45670 | F225: Orthopedics | G225: Cancelled | H225: 60 | I225: 10:30
A226: A00225 | B226: P0161 | C226: D027 | D226: 45805 | E226: 45792 | F226: ENT | G226: No-show | H226: 13 | I226: 16:00
A227: A00226 | B227: P0154 | C227: D018 | D227: 45689 | E227: 45686 | F227: Neurology | G227: Attended | H227: 3 | I227: 11:00
A228: A00227 | B228: P0496 | C228: D018 | D228: 45824 | E228: 45813 | F228: Neurology | G228: Attended | H228: 11 | I228: 15:30
A229: A00228 | B229: P0220 | C229: D015 | D229: 45742 | E229: 45723 | F229: Cardiology | G229: No-show | H229: 19 | I229: 16:00
A230: A00229 | B230: P0133 | C230: D012 | D230: 45694 | E230: 45682 | F230: Dermatology | G230: No-show | H230: 12 | I230: 09:00
A231: A00230 | B231: P0204 | C231: D013 | D231: 46009 | E231: 45990 | F231: Dermatology | G231: Attended | H231: 19 | I231: 16:00
A232: A00231 | B232: P0366 | C232: D015 | D232: 46016 | E232: 45957 | F232: Cardiology | G232: Attended | H232: 59 | I232: 08:30
... A308: A00307 | B308: P0459 | C308: D017 | D308: 45979 | E308: 45961 | F308: ENT | G308: Attended | H308: 18 | I308: 15:30
A309: A00308 | B309: P0622 | C309: D027 | D309: 45733 | E309: 45681 | F309: ENT | H309: 52 | I309: 10:30
A310: A00309 | B310: P0392 | C310: D022 | D310: 46000 | E310: 45973 | F310: Pediatrics | G310: Cancelled | H310: 27 | I310: 10:30
A311: A00310 | B311: P0130 | C311: D009 | D311: 45888 | E311: 45873 | F311: Neurology | G311: No-show | H311: 15 | I311: 11:00
A312: A00311 | B312: P0215 | C312: D025 | D312: 45924 | E312: 45880 | F312: Orthopedics | G312: Attended | H312: 44 | I312: 14:00
A313: A00312 | B313: P0121 | C313: D012 | D313: 45934 | E313: 45927 | F313: Dermatology | G313: Attended | H313: 7 | I313: 10:30
A314: A00313 | B314: P0216 | C314: D022 | D314: 45719 | E314: 45695 | F314: Pediatrics | G314: No-show | H314: 24 | I314: 08:30
A315: A00314 | B315: P0579 | C315: D028 | D315: 45930 | E315: 45883 | F315: Pediatrics | G315: No-show | H315: 47 | I315: 11:00
A316: A00315 | B316: P0124 | C316: D023 | D316: 45735 | E316: 45688 | F316: Pediatrics | G316: Attended | H316: 47 | I316: 13:30
A317: A00316 | B317: P0580 | C317: D004 | D317: 45757 | E317: 45742 | F317: Ophthalmology | G317: Attended | H317: 15 | I317: 13:30
A318: A00317 | B318: P0186 | C318: D006 | D318: 45700 | E318: 45690 | F318: Pediatrics | G318: Attended | H318: 10 | I318: 09:00
...

Sheet Patients
A1: patient_id | B1: age_group | C1: locality | D1: previous_visits | E1: previous_attendance_rate
A2: P0001 | B2: 45-59 | C2: Urban | D2: 3 | E2: 0.86
A3: P0002 | B3: 30-44 | C3: Rural | D3: 4 | E3: 0.88
A4: P0003 | B4: 60+ | C4: Suburban | D4: 4 | E4: 0.8
A5: P0004 | B5: 45-59 | C5: Urban | D5: 1 | E5: 0.95
A6: P0005 | B6: 0-17 | C6: Rural | D6: 1 | E6: 0.38
A7: P0006 | B7: 60+ | C7: Urban | D7: 4 | E7: 0.47
A8: P0007 | B8: 45-59 | C8: Rural | D8: 5 | E8: 0.84
A9: P0008 | B9: 45-59 | C9: Urban | D9: 6 | E9: 0.84
A10: P0009 | B10: 18-29 | C10: Suburban | D10: 4 | E10: 0.91
A11: P0010 | B11: 30-44 | C11: Urban | D11: 6 | E11: 0.93
A12: P0011 | B12: 30-44 | C12: Urban | D12: 4 | E12: 0.78
A13: P0012 | B13: 60+ | C13: Rural | D13: 2 | E13: 0.84
... A651: P0650 | B651: 0-17 | C651: Urban | D651: 2 | E651: 0.82

Sheet Doctors
A1: doctor_id | B1: specialty | C1: department | D1: clinic_schedule | E1: appointments_per_day_capacity
A2: D001 | B2: ENT Specialist | C2: ENT | D2: Mon-Sat AM | E2: 20
A3: D002 | B3: Pediatrician | C3: Pediatrics | D3: Mon-Sat AM | E3: 15
A4: D003 | B4: Orthopedic Surgeon | C4: Orthopedics | D4: Tue-Sat PM | E4: 12
A5: D004 | B5: Ophthalmologist | C5: Ophthalmology | D5: Mon-Fri PM | E5: 18
A6: D005 | B6: General Physician | C6: General Medicine | D6: Mon-Fri AM | E6: 12
A7: D006 | B7: Pediatrician | C7: Pediatrics | D7: Mon-Fri PM | E7: 15
A8: D007 | B8: Orthopedic Surgeon | C8: Orthopedics | D8: Mon-Sat AM | E8: 18
A9: D008 | B9: General Physician | C9: General Medicine | D9: Tue-Sat PM | E9: 18
A10: D009 | B10: Neurologist | C10: Neurology | D10: Mon-Fri PM | E10: 18
A11: D010 | B11: Cardiologist | C11: Cardiology | D11: Mon-Sat AM | E11: 20
A12: D011 | B12: ENT Specialist | C12: ENT | D12: Tue-Sat PM | E12: 12
A13: D012 | B13: Dermatologist | C13: Dermatology | D13: Tue-Sat PM | E13: 20
... A29: D028 | B29: Pediatrician | C29: Pediatrics | D29: Tue-Sat PM | E29: 20

Sheet Reminders
A1: reminder_id | B1: appointment_id | C1: reminder_type | D1: sent_status | E1: response | F1: sent_date
A2: R00001 | B2: A00001 | C2: SMS | D2: Yes | E2: Confirmed | F2: 45910
A3: R00002 | B3: A00002 | C3: SMS | D3: Yes | E3: No Response | F3: 45745
A4: R00003 | B4: A00003 | C4: SMS | D4: Yes | E4: Confirmed | F4: 45808
A5: R00004 | B5: A00004 | C5: SMS | D5: Yes | E5: No Response | F5: 45920
A6: R00005 | B6: A00005 | C6: Phone Call | D6: Yes | E6: Confirmed | F6: 46005
A7: R00006 | B7: A00006 | C7: SMS | D7: No | E7: Unknown
A8: R00007 | B8: A00007 | C8: SMS | D8: Yes | E8: Confirmed | F8: 45753
A9: R00008 | B9: A00008 | D9: Not Required | E9: No Response
A10: R00009 | B10: A00009 | C10: Email | D10: Yes | E10: No Response | F10: 45905
A11: R00010 | B11: A00010 | C11: SMS | D11: Yes | E11: Confirmed | F11: 45891
A12: R00011 | B12: A00011 | C12: SMS | D12: Yes | E12: Confirmed | F12: 45672
A13: R00012 | B13: A00012 | C13: SMS | D13: Yes | E13: Confirmed | F13: 45912
A14: R00013 | B14: A00013 | C14: SMS | D14: Yes | E14: No Response | F14: 45663
A15: R00014 | B15: A00014 | C15: SMS | D15: No | E15: Unknown
A16: R00015 | B16: A00015 | C16: SMS | D16: Yes | E16: Confirmed | F16: 45976
A17: R00016 | B17: A00016 | D17: Not Required | E17: No Response
A18: R00017 | B18: A00017 | D18: Not Required | E18: No Response
A19: R00018 | B19: A00018 | C19: Email | D19: Yes | E19: Cancelled | F19: 45680
A20: R00019 | B20: A00019 | C20: Phone Call | D20: Yes | E20: Confirmed | F20: 45975
A21: R00020 | B21: A00020 | C21: Email | D21: Yes | E21: Confirmed | F21: 45753
A22: R00021 | B22: A00021 | C22: Email | D22: Yes | E22: Cancelled | F22: 45750
A23: R00022 | B23: A00022 | D23: Not Required | E23: No Response
A24: R00023 | B24: A00023 | C24: Email | D24: No | E24: Unknown
A25: R00024 | B25: A00024 | C25: Email | D25: Yes | E25: Confirmed | F25: 45836
A26: R00025 | B26: A00025 | D26: Not Required | E26: No Response
A27: R00026 | B27: A00026 | C27: Phone Call | D27: Yes | E27: No Response | F27: 45856
A28: R00027 | B28: A00027 | C28: SMS | D28: Yes | E28: No Response | F28: 45762
A29: R00028 | B29: A00028 | C29: SMS | D29: Yes | E29: No Response | F29: 45872
A30: R00029 | B30: A00029 | C30: SMS | D30: Yes | E30: No Response | F30: 46007
A31: R00030 | B31: A00030 | C31: SMS | D31: Yes | E31: Confirmed | F31: 45794
A32: R00031 | B32: A00031 | C32: SMS | D32: Yes | E32: Confirmed | F32: 45937
A33: R00032 | B33: A00032 | C33: SMS | D33: Yes | E33: No Response | F33: 45939
A34: R00033 | B34: A00033 | C34: SMS | D34: Yes | E34: Confirmed | F34: 45966
A35: R00034 | B35: A00034 | D35: Not Required | E35: No Response
A36: R00035 | B36: A00035 | C36: SMS | D36: Yes | E36: No Response | F36: 45992
A37: R00036 | B37: A00036 | C37: SMS | D37: Yes | E37: No Response | F37: 45916
A38: R00037 | B38: A00037 | C38: SMS | D38: No | E38: Unknown
A39: R00038 | B39: A00038 | C39: SMS | D39: Yes | E39: Cancelled | F39: 45918
A40: R00039 | B40: A00039 | C40: Email | D40: Yes | E40: No Response | F40: 45960
...

Sheet Calendar
A1: date | B1: weekday | C1: is_weekend | D1: is_holiday | E1: season
A2: 45658 | B2: Wednesday | C2: FALSE | D2: TRUE | E2: Winter
A3: 45659 | B3: Thursday | C3: FALSE | D3: FALSE | E3: Winter
A4: 45660 | B4: Friday | C4: FALSE | D4: FALSE | E4: Winter
A5: 45661 | B5: Saturday | C5: TRUE | D5: FALSE | E5: Winter
A6: 45662 | B6: Sunday | C6: TRUE | D6: FALSE | E6: Winter
A7: 45663 | B7: Monday | C7: FALSE | D7: FALSE | E7: Winter
A8: 45664 | B8: Tuesday | C8: FALSE | D8: FALSE | E8: Winter
A9: 45665 | B9: Wednesday | C9: FALSE | D9: FALSE | E9: Winter
A10: 45666 | B10: Thursday | C10: FALSE | D10: FALSE | E10: Winter
A11: 45667 | B11: Friday | C11: FALSE | D11: FALSE | E11: Winter
A12: 45668 | B12: Saturday | C12: TRUE | D12: FALSE | E12: Winter
A13: 45669 | B13: Sunday | C13: TRUE | D13: FALSE | E13: Winter
... A366: 46022 | B366: Wednesday | C366: FALSE | D366: FALSE | E366: Winter

Sheet Department_Analysis
A3: Count of appointment_id | B3: Column Labels
A4: Row Labels | B4: Attended | C4: Cancelled | D4: No-show | E4: (blank) | F4: Grand Total
A5: Cardiology | B5: 247 | C5: 42 | D5: 181 | E5: 2 | F5: 472
A6: Dermatology | B6: 165 | C6: 41 | D6: 123 | E6: 6 | F6: 335
A7: ENT | B7: 256 | C7: 73 | D7: 225 | E7: 7 | F7: 561
A8: General Medicine | B8: 169 | C8: 35 | D8: 132 | E8: 4 | F8: 340
A9: Neurology | B9: 168 | C9: 29 | D9: 135 | E9: 2 | F9: 334
A10: Ophthalmology | B10: 67 | C10: 13 | D10: 34 | E10: 3 | F10: 117
A11: Orthopedics | B11: 179 | C11: 47 | D11: 115 | E11: 4 | F11: 345
A12: Pediatrics | B12: 356 | C12: 81 | D12: 249 | E12: 10 | F12: 696
A13: Grand Total | B13: 1607 | C13: 361 | D13: 1194 | E13: 38 | F13: 3200

Sheet Waiting_Analysis
A3: Count of appointment_id | B3: Column Labels
A4: Row Labels | B4: Attended | C4: Cancelled | D4: No-show | E4: (blank) | F4: Grand Total
A5: 0-3 days | B5: 150 | C5: 19 | D5: 69 | E5: 6 | F5: 244
A6: 15-30 days | B6: 437 | C6: 87 | D6: 287 | E6: 10 | F6: 821
A7: 31+ days | B7: 664 | C7: 206 | D7: 646 | E7: 15 | F7: 1531
A8: 4-7 days | B8: 128 | C8: 16 | D8: 65 | F8: 209
A9: 8-14 days | B9: 228 | C9: 33 | D9: 127 | E9: 7 | F9: 395
A10: Grand Total | B10: 1607 | C10: 361 | D10: 1194 | E10: 38 | F10: 3200

Sheet Daywise_Analysis
A3: Count of appointment_id | B3: Column Labels
A4: Row Labels | B4: Attended | C4: Cancelled | D4: No-show | E4: (blank) | F4: Grand Total
A5: Sunday | B5: 219 | C5: 57 | D5: 179 | E5: 5 | F5: 460
A6: Monday | B6: 236 | C6: 50 | D6: 162 | E6: 6 | F6: 454
A7: Tuesday | B7: 219 | C7: 41 | D7: 172 | E7: 5 | F7: 437
A8: Wednesday | B8: 271 | C8: 55 | D8: 154 | E8: 7 | F8: 487
A9: Thursday | B9: 231 | C9: 51 | D9: 158 | E9: 5 | F9: 445
A10: Friday | B10: 183 | C10: 54 | D10: 194 | E10: 4 | F10: 435
A11: Saturday | B11: 248 | C11: 53 | D11: 175 | E11: 6 | F11: 482
A12: Grand Total | B12: 1607 | C12: 361 | D12: 1194 | E12: 38 | F12: 3200

Sheet Reminder_Analysis
A3: Count of appointment_id | B3: Column Labels
A4: Row Labels | B4: Attended | C4: Cancelled | D4: No-show | E4: (blank) | F4: Grand Total
A5: Email | B5: 240 | C5: 56 | D5: 155 | E5: 9 | F5: 460
A6: Phone Call | B6: 287 | C6: 60 | D6: 220 | E6: 6 | F6: 573
A7: SMS | B7: 784 | C7: 169 | D7: 535 | E7: 14 | F7: 1502
A8: (blank) | B8: 296 | C8: 76 | D8: 284 | E8: 9 | F8: 665
A9: Grand Total | B9: 1607 | C9: 361 | D9: 1194 | E9: 38 | F9: 3200

Sheet Clinic_Utilization
A3: Row Labels | B3: Count of appointment_id
A4: Cardiologist | B4: 472
A5: Dermatologist | B5: 335
A6: ENT Specialist | B6: 561
A7: General Physician | B7: 340
A8: Neurologist | B8: 334
A9: Ophthalmologist | B9: 117
A10: Orthopedic Surgeon | B10: 345
A11: Pediatrician | B11: 696
A12: Grand Total | B12: 3200

Sheet Formula_Analysis
A1: Metric | B1: Result
A2: Total Appointments | B2: =COUNTA(Combined_Data!A2:A3201) -> 3200
A3: Attended Appointments | B3: =COUNTIF(Combined_Data!G2:G3201,"Attended") -> 1607
A4: No-show Appointments | B4: =COUNTIF(Combined_Data!G2:G3201,"No-show") -> 1194
A5: Cancelled Appointments | B5: =COUNTIF(Combined_Data!G2:G3201,"Cancelled") -> 361
A6: Missing Statuses | B6: =COUNTBLANK(Combined_Data!G2:G3201) -> 38
A7: Average Waiting Days | B7: =AVERAGE(Combined_Data!H2:H3201) -> 29.329687
A8: Median Waiting Days | B8: =MEDIAN(Combined_Data!H2:H3201) -> 29
A9: No-show Rate | B9: =IFERROR(B4/(B3+B4),0) -> 0.42627633

Sheet Combined_Data
A1: appointment_id | B1: patient_id | C1: doctor_id | D1: appointment_date | E1: booking_date | F1: department | G1: status | H1: waiting_days | I1: appointment_time | J1: age_group | K1: locality | L1: previous_visits | M1: previous_attendance_rate | N1: specialty | O1: clinic_schedule | P1: appointments_per_day_capacity | Q1: reminder_type | R1: sent_status | S1: response | T1: sent_date | U1: weekday | V1: is_weekend | W1: is_holiday | X1: season | Y1: No_show_flag | Z1: Waiting_Category | AA1: Attendance_History_Group | AB1: Outcome_Group
A2: A00001 | B2: P0589 | C2: D014 | D2: 45913 | E2: 45877 | F2: Dermatology | G2: Attended | H2: 36 | I2: 09:00 | J2: 18-29 | K2: Urban | L2: 4 | M2: 0.56 | N2: Dermatologist | O2: Tue-Sat PM | P2: 15 | Q2: SMS | R2: Yes | S2: Confirmed | T2: 45910 | U2: Saturday | V2: TRUE | W2: FALSE | X2: Autumn | Y2: =IF(G2="No-show",1,IF(G2="Attended",0,"")) -> 0 | Z2: =IF(H2="","Unknown",IF(H2<=3,"0-3 days",IF(H2<=7,"4-7 days",IF(H2<=14,"8-14 days",IF(H2<=30,"15-30 days","31+ days"))))) -> 31+ days | AA2: =IF(M2="","Unknown",IF(M2<0.5,"Low",IF(M2<0.75,"Moderate",IF(M2<0.9,"Good","Very Good")))) -> Moderate | AB2: =IF(G2="Attended","Attended",IF(G2="No-show","No-show","Excluded")) -> Attended
A3: A00002 | B3: P0572 | C3: D025 | D3: 45746 | E3: 45707 | F3: Orthopedics | G3: Attended | H3: 39 | I3: 14:00 | J3: 60+ | K3: Urban | L3: 2 | M3: 0.63 | N3: Orthopedic Surgeon | O3: Mon-Fri AM | P3: 12 | Q3: SMS | R3: Yes | S3: No Response | T3: 45745 | U3: Sunday | V3: TRUE | W3: FALSE | X3: Summer | Y3: =IF(G3="No-show",1,IF(G3="Attended",0,"")) -> 0 | Z3: =IF(H3="","Unknown",IF(H3<=3,"0-3 days",IF(H3<=7,"4-7 days",IF(H3<=14,"8-14 days",IF(H3<=30,"15-30 days","31+ days"))))) -> 31+ days | AA3: =IF(M3="","Unknown",IF(M3<0.5,"Low",IF(M3<0.75,"Moderate",IF(M3<0.9,"Good","Very Good")))) -> Moderate | AB3: =IF(G3="Attended","Attended",IF(G3="No-show","No-show","Excluded")) -> Attended
A4: A00003 | B4: P0501 | C4: D023 | D4: 45809 | E4: 45784 | F4: Pediatrics | G4: No-show | H4: 25 | I4: 09:00 | J4: 45-59 | K4: Urban | L4: 5 | M4: 0.78 | N4: Pediatrician | O4: Mon-Fri PM | P4: 18 | Q4: SMS | R4: Yes | S4: Confirmed | T4: 45808 | U4: Sunday | V4: TRUE | W4: FALSE | X4: Monsoon | Y4: =IF(G4="No-show",1,IF(G4="Attended",0,"")) -> 1 | Z4: =IF(H4="","Unknown",IF(H4<=3,"0-3 days",IF(H4<=7,"4-7 days",IF(H4<=14,"8-14 days",IF(H4<=30,"15-30 days","31+ days"))))) -> 15-30 days | AA4: =IF(M4="","Unknown",IF(M4<0.5,"Low",IF(M4<0.75,"Moderate",IF(M4<0.9,"Good","Very Good")))) -> Good | AB4: =IF(G4="Attended","Attended",IF(G4="No-show","No-show","Excluded")) -> No-show
A5: A00004 | B5: P0070 | C5: D011 | D5: 45921 | E5: 45919 | F5: ENT | G5: No-show | H5: 2 | I5: 09:00 | J5: 30-44 | K5: Rural | L5: 3 | M5: 0.79 | N5: ENT Specialist | O5: Tue-Sat PM | P5: 12 | Q5: SMS | R5: Yes | S5: No Response | T5: 45920 | U5: Sunday | V5: TRUE | W5: FALSE | X5: Autumn | Y5: =IF(G5="No-show",1,IF(G5="Attended",0,"")) -> 1 | Z5: =IF(H5="","Unknown",IF(H5<=3,"0-3 days",IF(H5<=7,"4-7 days",IF(H5<=14,"8-14 days",IF(H5<=30,"15-30 days","31+ days"))))) -> 0-3 days | AA5: =IF(M5="","Unknown",IF(M5<0.5,"Low",IF(M5<0.75,"Moderate",IF(M5<0.9,"Good","Very Good")))) -> Good | AB5: =IF(G5="Attended","Attended",IF(G5="No-show","No-show","Excluded")) -> No-show
A6: A00005 | B6: P0319 | C6: D008 | D6: 46007 | E6: 45952 | F6: General Medicine | G6: Attended | H6: 55 | I6: 13:30 | J6: 18-29 | K6: Suburban | L6: 1 | M6: 0.84 | N6: General Physician | O6: Tue-Sat PM | P6: 18 | Q6: Phone Call | R6: Yes | S6: Confirmed | T6: 46005 | U6: Tuesday | V6: FALSE | W6: FALSE | X6: Winter | Y6: =IF(G6="No-show",1,IF(G6="Attended",0,"")) -> 0 | Z6: =IF(H6="","Unknown",IF(H6<=3,"0-3 days",IF(H6<=7,"4-7 days",IF(H6<=14,"8-14 days",IF(H6<=30,"15-30 days","31+ days"))))) -> 31+ days | AA6: =IF(M6="","Unknown",IF(M6<0.5,"Low",IF(M6<0.75,"Moderate",IF(M6<0.9,"Good","Very Good")))) -> Good | AB6: =IF(G6="Attended","Attended",IF(G6="No-show","No-show","Excluded")) -> Attended
A7: A00006 | B7: P0315 | C7: D028 | D7: 45867 | E7: 45855 | F7: Pediatrics | G7: Attended | H7: 12 | I7: 10:30 | J7: 30-44 | K7: Rural | L7: 4 | M7: 0.9 | N7: Pediatrician | O7: Tue-Sat PM | P7: 20 | Q7: SMS | R7: No | S7: Unknown | U7: Tuesday | V7: FALSE | W7: FALSE | X7: Monsoon | Y7: =IF(G7="No-show",1,IF(G7="Attended",0,"")) -> 0 | Z7: =IF(H7="","Unknown",IF(H7<=3,"0-3 days",IF(H7<=7,"4-7 days",IF(H7<=14,"8-14 days",IF(H7<=30,"15-30 days","31+ days"))))) -> 8-14 days | AA7: =IF(M7="","Unknown",IF(M7<0.5,"Low",IF(M7<0.75,"Moderate",IF(M7<0.9,"Good","Very Good")))) -> Very Good | AB7: =IF(G7="Attended","Attended",IF(G7="No-show","No-show","Excluded")) -> Attended
A8: A00007 | B8: P0415 | C8: D016 | D8: 45756 | E8: 45697 | F8: Cardiology | G8: Attended | H8: 59 | I8: 08:30 | J8: 0-17 | K8: Urban | L8: 2 | M8: 0.66 | N8: Cardiologist | O8: Mon-Fri PM | P8: 18 | Q8: SMS | R8: Yes | S8: Confirmed | T8: 45753 | U8: Wednesday | V8: FALSE | W8: FALSE | X8: Summer | Y8: =IF(G8="No-show",1,IF(G8="Attended",0,"")) -> 0 | Z8: =IF(H8="","Unknown",IF(H8<=3,"0-3 days",IF(H8<=7,"4-7 days",IF(H8<=14,"8-14 days",IF(H8<=30,"15-30 days","31+ days"))))) -> 31+ days | AA8: =IF(M8="","Unknown",IF(M8<0.5,"Low",IF(M8<0.75,"Moderate",IF(M8<0.9,"Good","Very Good")))) -> Moderate | AB8: =IF(G8="Attended","Attended",IF(G8="No-show","No-show","Excluded")) -> Attended
A9: A00008 | B9: P0550 | C9: D004 | D9: 45912 | E9: 45856 | F9: Ophthalmology | G9: No-show | H9: 56 | I9: 16:00 | J9: 30-44 | K9: Suburban | L9: 5 | M9: 0.82 | N9: Ophthalmologist | O9: Mon-Fri PM | P9: 18 | R9: Not Required | S9: No Response | U9: Friday | V9: FALSE | W9: FALSE | X9: Autumn | Y9: =IF(G9="No-show",1,IF(G9="Attended",0,"")) -> 1 | Z9: =IF(H9="","Unknown",IF(H9<=3,"0-3 days",IF(H9<=7,"4-7 days",IF(H9<=14,"8-14 days",IF(H9<=30,"15-30 days","31+ days"))))) -> 31+ days | AA9: =IF(M9="","Unknown",IF(M9<0.5,"Low",IF(M9<0.75,"Moderate",IF(M9<0.9,"Good","Very Good")))) -> Good | AB9: =IF(G9="Attended","Attended",IF(G9="No-show","No-show","Excluded")) -> No-show
A10: A00009 | B10: P0209 | C10: D007 | D10: 45908 | E10: 45907 | F10: Orthopedics | G10: No-show | H10: 1 | I10: 16:00 | J10: 18-29 | K10: Urban | L10: 8 | M10: 0.68 | N10: Orthopedic Surgeon | O10: Mon-Sat AM | P10: 18 | Q10: Email | R10: Yes | S10: No Response | T10: 45905 | U10: Monday | V10: FALSE | W10: FALSE | X10: Autumn | Y10: =IF(G10="No-show",1,IF(G10="Attended",0,"")) -> 1 | Z10: =IF(H10="","Unknown",IF(H10<=3,"0-3 days",IF(H10<=7,"4-7 days",IF(H10<=14,"8-14 days",IF(H10<=30,"15-30 days","31+ days"))))) -> 0-3 days | AA10: =IF(M10="","Unknown",IF(M10<0.5,"Low",IF(M10<0.75,"Moderate",IF(M10<0.9,"Good","Very Good")))) -> Moderate | AB10: =IF(G10="Attended","Attended",IF(G10="No-show","No-show","Excluded")) -> No-show
A11: A00010 | B11: P0363 | C11: D024 | D11: 45893 | E11: 45848 | F11: Neurology | G11: Cancelled | H11: 45 | I11: 13:30 | J11: 18-29 | K11: Urban | L11: 3 | M11: 0.85 | N11: Neurologist | O11: Mon-Sat AM | P11: 20 | Q11: SMS | R11: Yes | S11: Confirmed | T11: 45891 | U11: Sunday | V11: TRUE | W11: FALSE | X11: Monsoon | Y11: =IF(G11="No-show",1,IF(G11="Attended",0,"")) | Z11: =IF(H11="","Unknown",IF(H11<=3,"0-3 days",IF(H11<=7,"4-7 days",IF(H11<=14,"8-14 days",IF(H11<=30,"15-30 days","31+ days"))))) -> 31+ days | AA11: =IF(M11="","Unknown",IF(M11<0.5,"Low",IF(M11<0.75,"Moderate",IF(M11<0.9,"Good","Very Good")))) -> Good | AB11: =IF(G11="Attended","Attended",IF(G11="No-show","No-show","Excluded")) -> Excluded
A12: A00011 | B12: P0172 | C12: D026 | D12: 45674 | E12: 45636 | F12: General Medicine | G12: No-show | H12: 38 | I12: 13:30 | J12: 30-44 | K12: Suburban | L12: 5 | M12: 0.74 | N12: General Physician | O12: Mon-Sat AM | P12: 15 | Q12: SMS | R12: Yes | S12: Confirmed | T12: 45672 | U12: Friday | V12: FALSE | W12: FALSE | X12: Winter | Y12: =IF(G12="No-show",1,IF(G12="Attended",0,"")) -> 1 | Z12: =IF(H12="","Unknown",IF(H12<=3,"0-3 days",IF(H12<=7,"4-7 days",IF(H12<=14,"8-14 days",IF(H12<=30,"15-30 days","31+ days"))))) -> 31+ days | AA12: =IF(M12="","Unknown",IF(M12<0.5,"Low",IF(M12<0.75,"Moderate",IF(M12<0.9,"Good","Very Good")))) -> Moderate | AB12: =IF(G12="Attended","Attended",IF(G12="No-show","No-show","Excluded")) -> No-show
A13: A00012 | B13: P0137 | C13: D026 | D13: 45915 | E13: 45901 | F13: General Medicine | G13: No-show | H13: 14 | I13: 15:30 | J13: 60+ | K13: Rural | L13: 3 | M13: 0.88 | N13: General Physician | O13: Mon-Sat AM | P13: 15 | Q13: SMS | R13: Yes | S13: Confirmed | T13: 45912 | U13: Monday | V13: FALSE | W13: FALSE | X13: Autumn | Y13: =IF(G13="No-show",1,IF(G13="Attended",0,"")) -> 1 | Z13: =IF(H13="","Unknown",IF(H13<=3,"0-3 days",IF(H13<=7,"4-7 days",IF(H13<=14,"8-14 days",IF(H13<=30,"15-30 days","31+ days"))))) -> 8-14 days | AA13: =IF(M13="","Unknown",IF(M13<0.5,"Low",IF(M13<0.75,"Moderate",IF(M13<0.9,"Good","Very Good")))) -> Good | AB13: =IF(G13="Attended","Attended",IF(G13="No-show","No-show","Excluded")) -> No-show
A14: A00013 | B14: P0204 | C14: D001 | D14: 45665 | E14: 45616 | F14: ENT | G14: Attended | H14: 49 | I14: 16:00 | J14: 18-29 | K14: Rural | L14: 3 | M14: 0.82 | N14: ENT Specialist | O14: Mon-Sat AM | P14: 20 | Q14: SMS | R14: Yes | S14: No Response | T14: 45663 | U14: Wednesday | V14: FALSE | W14: FALSE | X14: Winter | Y14: =IF(G14="No-show",1,IF(G14="Attended",0,"")) -> 0 | Z14: =IF(H14="","Unknown",IF(H14<=3,"0-3 days",IF(H14<=7,"4-7 days",IF(H14<=14,"8-14 days",IF(H14<=30,"15-30 days","31+ days"))))) -> 31+ days | AA14: =IF(M14="","Unknown",IF(M14<0.5,"Low",IF(M14<0.75,"Moderate",IF(M14<0.9,"Good","Very Good")))) -> Good | AB14: =IF(G14="Attended","Attended",IF(G14="No-show","No-show","Excluded")) -> Attended
A15: A00014 | B15: P0479 | C15: D024 | D15: 45988 | E15: 45982 | F15: Neurology | G15: Attended | H15: 6 | I15: 08:30 | J15: 45-59 | K15: Suburban | L15: 1 | M15: 0.83 | N15: Neurologist | O15: Mon-Sat AM | P15: 20 | Q15: SMS | R15: No | S15: Unknown | U15: Thursday | V15: FALSE | W15: FALSE | X15: Autumn | Y15: =IF(G15="No-show",1,IF(G15="Attended",0,"")) -> 0 | Z15: =IF(H15="","Unknown",IF(H15<=3,"0-3 days",IF(H15<=7,"4-7 days",IF(H15<=14,"8-14 days",IF(H15<=30,"15-30 days","31+ days"))))) -> 4-7 days | AA15: =IF(M15="","Unknown",IF(M15<0.5,"Low",IF(M15<0.75,"Moderate",IF(M15<0.9,"Good","Very Good")))) -> Good | AB15: =IF(G15="Attended","Attended",IF(G15="No-show","No-show","Excluded")) -> Attended
A16: A00015 | B16: P0285 | C16: D004 | D16: 45979 | E16: 45964 | F16: Ophthalmology | G16: Attended | H16: 15 | I16: 08:30 | J16: 30-44 | K16: Suburban | L16: 2 | M16: 0.6 | N16: Ophthalmologist | O16: Mon-Fri PM | P16: 18 | Q16: SMS | R16: Yes | S16: Confirmed | T16: 45976 | U16: Tuesday | V16: FALSE | W16: FALSE | X16: Autumn | Y16: =IF(G16="No-show",1,IF(G16="Attended",0,"")) -> 0 | Z16: =IF(H16="","Unknown",IF(H16<=3,"0-3 days",IF(H16<=7,"4-7 days",IF(H16<=14,"8-14 days",IF(H16<=30,"15-30 days","31+ days"))))) -> 15-30 days | AA16: =IF(M16="","Unknown",IF(M16<0.5,"Low",IF(M16<0.75,"Moderate",IF(M16<0.9,"Good","Very Good")))) -> Moderate | AB16: =IF(G16="Attended","Attended",IF(G16="No-show","No-show","Excluded")) -> Attended
A17: A00016 | B17: P0443 | C17: D023 | D17: 45863 | E17: 45806 | F17: Pediatrics | G17: No-show | H17: 57 | I17: 10:30 | J17: 45-59 | K17: Urban | L17: 4 | M17: 0.77 | N17: Pediatrician | O17: Mon-Fri PM | P17: 18 | R17: Not Required | S17: No Response | U17: Friday | V17: FALSE | W17: FALSE | X17: Monsoon | Y17: =IF(G17="No-show",1,IF(G17="Attended",0,"")) -> 1 | Z17: =IF(H17="","Unknown",IF(H17<=3,"0-3 days",IF(H17<=7,"4-7 days",IF(H17<=14,"8-14 days",IF(H17<=30,"15-30 days","31+ days"))))) -> 31+ days | AA17: =IF(M17="","Unknown",IF(M17<0.5,"Low",IF(M17<0.75,"Moderate",IF(M17<0.9,"Good","Very Good")))) -> Good | AB17: =IF(G17="Attended","Attended",IF(G17="No-show","No-show","Excluded")) -> No-show
A18: A00017 | B18: P0450 | C18: D025 | D18: 45893 | E18: 45848 | F18: Orthopedics | G18: No-show | H18: 45 | I18: 10:30 | J18: 45-59 | K18: Urban | L18: 2 | M18: 0.67 | N18: Orthopedic Surgeon | O18: Mon-Fri AM | P18: 12 | R18: Not Required | S18: No Response | U18: Sunday | V18: TRUE | W18: FALSE | X18: Monsoon | Y18: =IF(G18="No-show",1,IF(G18="Attended",0,"")) -> 1 | Z18: =IF(H18="","Unknown",IF(H18<=3,"0-3 days",IF(H18<=7,"4-7 days",IF(H18<=14,"8-14 days",IF(H18<=30,"15-30 days","31+ days"))))) -> 31+ days | AA18: =IF(M18="","Unknown",IF(M18<0.5,"Low",IF(M18<0.75,"Moderate",IF(M18<0.9,"Good","Very Good")))) -> Moderate | AB18: =IF(G18="Attended","Attended",IF(G18="No-show","No-show","Excluded")) -> No-show
A19: A00018 | B19: P0236 | C19: D011 | D19: 45682 | E19: 45676 | F19: ENT | G19: Attended | H19: 6 | I19: 16:00 | J19: 45-59 | K19: Urban | L19: 3 | M19: 0.8 | N19: ENT Specialist | O19: Tue-Sat PM | P19: 12 | Q19: Email | R19: Yes | S19: Cancelled | T19: 45680 | U19: Saturday | V19: TRUE | W19: FALSE | X19: Winter | Y19: =IF(G19="No-show",1,IF(G19="Attended",0,"")) -> 0 | Z19: =IF(H19="","Unknown",IF(H19<=3,"0-3 days",IF(H19<=7,"4-7 days",IF(H19<=14,"8-14 days",IF(H19<=30,"15-30 days","31+ days"))))) -> 4-7 days | AA19: =IF(M19="","Unknown",IF(M19<0.5,"Low",IF(M19<0.75,"Moderate",IF(M19<0.9,"Good","Very Good")))) -> Good | AB19: =IF(G19="Attended","Attended",IF(G19="No-show","No-show","Excluded")) -> Attended
A20: A00019 | B20: P0621 | C20: D006 | D20: 45977 | E20: 45969 | F20: Pediatrics | G20: Cancelled | H20: 8 | I20: 13:30 | J20: 45-59 | K20: Rural | L20: 1 | M20: 0.91 | N20: Pediatrician | O20: Mon-Fri PM | P20: 15 | Q20: Phone Call | R20: Yes | S20: Confirmed | T20: 45975 | U20: Sunday | V20: TRUE | W20: FALSE | X20: Autumn | Y20: =IF(G20="No-show",1,IF(G20="Attended",0,"")) | Z20: =IF(H20="","Unknown",IF(H20<=3,"0-3 days",IF(H20<=7,"4-7 days",IF(H20<=14,"8-14 days",IF(H20<=30,"15-30 days","31+ days"))))) -> 8-14 days | AA20: =IF(M20="","Unknown",IF(M20<0.5,"Low",IF(M20<0.75,"Moderate",IF(M20<0.9,"Good","Very Good")))) -> Very Good | AB20: =IF(G20="Attended","Attended",IF(G20="No-show","No-show","Excluded")) -> Excluded
A21: A00020 | B21: P0031 | C21: D020 | D21: 45756 | E21: 45741 | F21: Cardiology | G21: Attended | H21: 15 | I21: 15:30 | J21: 45-59 | K21: Urban | L21: 4 | M21: 0.89 | N21: Cardiologist | O21: Mon-Sat AM | P21: 12 | Q21: Email | R21: Yes | S21: Confirmed | T21: 45753 | U21: Wednesday | V21: FALSE | W21: FALSE | X21: Summer | Y21: =IF(G21="No-show",1,IF(G21="Attended",0,"")) -> 0 | Z21: =IF(H21="","Unknown",IF(H21<=3,"0-3 days",IF(H21<=7,"4-7 days",IF(H21<=14,"8-14 days",IF(H21<=30,"15-30 days","31+ days"))))) -> 15-30 days | AA21: =IF(M21="","Unknown",IF(M21<0.5,"Low",IF(M21<0.75,"Moderate",IF(M21<0.9,"Good","Very Good")))) -> Good | AB21: =IF(G21="Attended","Attended",IF(G21="No-show","No-show","Excluded")) -> Attended
A22: A00021 | B22: P0583 | C22: D002 | D22: 45753 | E22: 45749 | F22: Pediatrics | G22: Attended | H22: 4 | I22: 14:00 | J22: 18-29 | K22: Urban | L22: 4 | M22: 0.87 | N22: Pediatrician | O22: Mon-Sat AM | P22: 15 | Q22: Email | R22: Yes | S22: Cancelled | T22: 45750 | U22: Sunday | V22: TRUE | W22: FALSE | X22: Summer | Y22: =IF(G22="No-show",1,IF(G22="Attended",0,"")) -> 0 | Z22: =IF(H22="","Unknown",IF(H22<=3,"0-3 days",IF(H22<=7,"4-7 days",IF(H22<=14,"8-14 days",IF(H22<=30,"15-30 days","31+ days"))))) -> 4-7 days | AA22: =IF(M22="","Unknown",IF(M22<0.5,"Low",IF(M22<0.75,"Moderate",IF(M22<0.9,"Good","Very Good")))) -> Good | AB22: =IF(G22="Attended","Attended",IF(G22="No-show","No-show","Excluded")) -> Attended
A23: A00022 | B23: P0006 | C23: D017 | D23: 45916 | E23: 45905 | F23: ENT | G23: No-show | H23: 11 | I23: 14:00 | J23: 60+ | K23: Urban | L23: 4 | M23: 0.47 | N23: ENT Specialist | O23: Mon-Fri PM | P23: 18 | R23: Not Required | S23: No Response | U23: Tuesday | V23: FALSE | W23: FALSE | X23: Autumn | Y23: =IF(G23="No-show",1,IF(G23="Attended",0,"")) -> 1 | Z23: =IF(H23="","Unknown",IF(H23<=3,"0-3 days",IF(H23<=7,"4-7 days",IF(H23<=14,"8-14 days",IF(H23<=30,"15-30 days","31+ days"))))) -> 8-14 days | AA23: =IF(M23="","Unknown",IF(M23<0.5,"Low",IF(M23<0.75,"Moderate",IF(M23<0.9,"Good","Very Good")))) -> Low | AB23: =IF(G23="Attended","Attended",IF(G23="No-show","No-show","Excluded")) -> No-show
A24: A00023 | B24: P0249 | C24: D010 | D24: 46000 | E24: 45966 | F24: Cardiology | G24: No-show | H24: 34 | I24: 16:00 | J24: 30-44 | K24: Urban | L24: 2 | M24: 0.83 | N24: Cardiologist | O24: Mon-Sat AM | P24: 20 | Q24: Email | R24: No | S24: Unknown | U24: Tuesday | V24: FALSE | W24: FALSE | X24: Winter | Y24: =IF(G24="No-show",1,IF(G24="Attended",0,"")) -> 1 | Z24: =IF(H24="","Unknown",IF(H24<=3,"0-3 days",IF(H24<=7,"4-7 days",IF(H24<=14,"8-14 days",IF(H24<=30,"15-30 days","31+ days"))))) -> 31+ days | AA24: =IF(M24="","Unknown",IF(M24<0.5,"Low",IF(M24<0.75,"Moderate",IF(M24<0.9,"Good","Very Good")))) -> Good | AB24: =IF(G24="Attended","Attended",IF(G24="No-show","No-show","Excluded")) -> No-show
A25: A00024 | B25: P0537 | C25: D012 | D25: 45838 | E25: 45838 | F25: Dermatology | G25: Attended | H25: 0 | I25: 13:30 | J25: 30-44 | K25: Urban | L25: 3 | M25: 0.89 | N25: Dermatologist | O25: Tue-Sat PM | P25: 20 | Q25: Email | R25: Yes | S25: Confirmed | T25: 45836 | U25: Monday | V25: FALSE | W25: FALSE | X25: Monsoon | Y25: =IF(G25="No-show",1,IF(G25="Attended",0,"")) -> 0 | Z25: =IF(H25="","Unknown",IF(H25<=3,"0-3 days",IF(H25<=7,"4-7 days",IF(H25<=14,"8-14 days",IF(H25<=30,"15-30 days","31+ days"))))) -> 0-3 days | AA25: =IF(M25="","Unknown",IF(M25<0.5,"Low",IF(M25<0.75,"Moderate",IF(M25<0.9,"Good","Very Good")))) -> Good | AB25: =IF(G25="Attended","Attended",IF(G25="No-show","No-show","Excluded")) -> Attended
A26: A00025 | B26: P0445 | C26: D024 | D26: 45843 | E26: 45826 | F26: Neurology | G26: Attended | H26: 17 | I26: 15:30 | J26: 18-29 | K26: Suburban | L26: 4 | M26: 0.74 | N26: Neurologist | O26: Mon-Sat AM | P26: 20 | R26: Not Required | S26: No Response | U26: Saturday | V26: TRUE | W26: FALSE | X26: Monsoon | Y26: =IF(G26="No-show",1,IF(G26="Attended",0,"")) -> 0 | Z26: =IF(H26="","Unknown",IF(H26<=3,"0-3 days",IF(H26<=7,"4-7 days",IF(H26<=14,"8-14 days",IF(H26<=30,"15-30 days","31+ days"))))) -> 15-30 days | AA26: =IF(M26="","Unknown",IF(M26<0.5,"Low",IF(M26<0.75,"Moderate",IF(M26<0.9,"Good","Very Good")))) -> Moderate | AB26: =IF(G26="Attended","Attended",IF(G26="No-show","No-show","Excluded")) -> Attended
A27: A00026 | B27: P0210 | C27: D028 | D27: 45858 | E27: 45839 | F27: Pediatrics | G27: Cancelled | H27: 19 | I27: 10:30 | J27: 30-44 | K27: Suburban | L27: 4 | M27: 0.68 | N27: Pediatrician | O27: Tue-Sat PM | P27: 20 | Q27: Phone Call | R27: Yes | S27: No Response | T27: 45856 | U27: Sunday | V27: TRUE | W27: FALSE | X27: Monsoon | Y27: =IF(G27="No-show",1,IF(G27="Attended",0,"")) | Z27: =IF(H27="","Unknown",IF(H27<=3,"0-3 days",IF(H27<=7,"4-7 days",IF(H27<=14,"8-14 days",IF(H27<=30,"15-30 days","31+ days"))))) -> 15-30 days | AA27: =IF(M27="","Unknown",IF(M27<0.5,"Low",IF(M27<0.75,"Moderate",IF(M27<0.9,"Good","Very Good")))) -> Moderate | AB27: =IF(G27="Attended","Attended",IF(G27="No-show","No-show","Excluded")) -> Excluded
A28: A00027 | B28: P0576 | C28: D012 | D28: 45764 | E28: 45705 | F28: Dermatology | G28: No-show | H28: 59 | I28: 10:30 | J28: 30-44 | K28: Rural | L28: 6 | M28: 0.94 | N28: Dermatologist | O28: Tue-Sat PM | P28: 20 | Q28: SMS | R28: Yes | S28: No Response | T28: 45762 | U28: Thursday | V28: FALSE | W28: FALSE | X28: Summer | Y28: =IF(G28="No-show",1,IF(G28="Attended",0,"")) -> 1 | Z28: =IF(H28="","Unknown",IF(H28<=3,"0-3 days",IF(H28<=7,"4-7 days",IF(H28<=14,"8-14 days",IF(H28<=30,"15-30 days","31+ days"))))) -> 31+ days | AA28: =IF(M28="","Unknown",IF(M28<0.5,"Low",IF(M28<0.75,"Moderate",IF(M28<0.9,"Good","Very Good")))) -> Very Good | AB28: =IF(G28="Attended","Attended",IF(G28="No-show","No-show","Excluded")) -> No-show
A29: A00028 | B29: P0090 | C29: D009 | D29: 45875 | E29: 45816 | F29: Neurology | G29: No-show | H29: 59 | I29: 13:30 | J29: 30-44 | K29: Urban | L29: 4 | M29: 0.79 | N29: Neurologist | O29: Mon-Fri PM | P29: 18 | Q29: SMS | R29: Yes | S29: No Response | T29: 45872 | U29: Wednesday | V29: FALSE | W29: FALSE | X29: Monsoon | Y29: =IF(G29="No-show",1,IF(G29="Attended",0,"")) -> 1 | Z29: =IF(H29="","Unknown",IF(H29<=3,"0-3 days",IF(H29<=7,"4-7 days",IF(H29<=14,"8-14 days",IF(H29<=30,"15-30 days","31+ days"))))) -> 31+ days | AA29: =IF(M29="","Unknown",IF(M29<0.5,"Low",IF(M29<0.75,"Moderate",IF(M29<0.9,"Good","Very Good")))) -> Good | AB29: =IF(G29="Attended","Attended",IF(G29="No-show","No-show","Excluded")) -> No-show
A30: A00029 | B30: P0436 | C30: D024 | D30: 46008 | E30: 45957 | F30: Neurology | G30: Attended | H30: 51 | I30: 16:00 | J30: 18-29 | K30: Suburban | L30: 1 | M30: 0.92 | N30: Neurologist | O30: Mon-Sat AM | P30: 20 | Q30: SMS | R30: Yes | S30: No Response | T30: 46007 | U30: Wednesday | V30: FALSE | W30: FALSE | X30: Winter | Y30: =IF(G30="No-show",1,IF(G30="Attended",0,"")) -> 0 | Z30: =IF(H30="","Unknown",IF(H30<=3,"0-3 days",IF(H30<=7,"4-7 days",IF(H30<=14,"8-14 days",IF(H30<=30,"15-30 days","31+ days"))))) -> 31+ days | AA30: =IF(M30="","Unknown",IF(M30<0.5,"Low",IF(M30<0.75,"Moderate",IF(M30<0.9,"Good","Very Good")))) -> Very Good | AB30: =IF(G30="Attended","Attended",IF(G30="No-show","No-show","Excluded")) -> Attended
A31: A00030 | B31: P0338 | C31: D012 | D31: 45797 | E31: 45777 | F31: Dermatology | G31: Attended | H31: 20 | I31: 08:30 | J31: 45-59 | K31: Urban | L31: 2 | M31: 0.94 | N31: Dermatologist | O31: Tue-Sat PM | P31: 20 | Q31: SMS | R31: Yes | S31: Confirmed | T31: 45794 | U31: Tuesday | V31: FALSE | W31: FALSE | X31: Summer | Y31: =IF(G31="No-show",1,IF(G31="Attended",0,"")) -> 0 | Z31: =IF(H31="","Unknown",IF(H31<=3,"0-3 days",IF(H31<=7,"4-7 days",IF(H31<=14,"8-14 days",IF(H31<=30,"15-30 days","31+ days"))))) -> 15-30 days | AA31: =IF(M31="","Unknown",IF(M31<0.5,"Low",IF(M31<0.75,"Moderate",IF(M31<0.9,"Good","Very Good")))) -> Very Good | AB31: =IF(G31="Attended","Attended",IF(G31="No-show","No-show","Excluded")) -> Attended
A32: A00031 | B32: P0135 | C32: D006 | D32: 45940 | E32: 45908 | F32: Pediatrics | G32: Attended | H32: 32 | I32: 13:30 | J32: 45-59 | K32: Rural | L32: 1 | M32: 0.81 | N32: Pediatrician | O32: Mon-Fri PM | P32: 15 | Q32: SMS | R32: Yes | S32: Confirmed | T32: 45937 | U32: Friday | V32: FALSE | W32: FALSE | X32: Autumn | Y32: =IF(G32="No-show",1,IF(G32="Attended",0,"")) -> 0 | Z32: =IF(H32="","Unknown",IF(H32<=3,"0-3 days",IF(H32<=7,"4-7 days",IF(H32<=14,"8-14 days",IF(H32<=30,"15-30 days","31+ days"))))) -> 31+ days | AA32: =IF(M32="","Unknown",IF(M32<0.5,"Low",IF(M32<0.75,"Moderate",IF(M32<0.9,"Good","Very Good")))) -> Good | AB32: =IF(G32="Attended","Attended",IF(G32="No-show","No-show","Excluded")) -> Attended
A33: A00032 | B33: P0599 | C33: D026 | D33: 45940 | E33: 45910 | F33: General Medicine | G33: Attended | H33: 30 | I33: 09:00 | J33: 60+ | K33: Rural | L33: 5 | M33: 0.87 | N33: General Physician | O33: Mon-Sat AM | P33: 15 | Q33: SMS | R33: Yes | S33: No Response | T33: 45939 | U33: Friday | V33: FALSE | W33: FALSE | X33: Autumn | Y33: =IF(G33="No-show",1,IF(G33="Attended",0,"")) -> 0 | Z33: =IF(H33="","Unknown",IF(H33<=3,"0-3 days",IF(H33<=7,"4-7 days",IF(H33<=14,"8-14 days",IF(H33<=30,"15-30 days","31+ days"))))) -> 15-30 days | AA33: =IF(M33="","Unknown",IF(M33<0.5,"Low",IF(M33<0.75,"Moderate",IF(M33<0.9,"Good","Very Good")))) -> Good | AB33: =IF(G33="Attended","Attended",IF(G33="No-show","No-show","Excluded")) -> Attended
A34: A00033 | B34: P0498 | C34: D028 | D34: 45968 | E34: 45916 | F34: Pediatrics | G34: No-show | H34: 52 | I34: 16:00 | J34: 45-59 | K34: Rural | L34: 4 | M34: 0.87 | N34: Pediatrician | O34: Tue-Sat PM | P34: 20 | Q34: SMS | R34: Yes | S34: Confirmed | T34: 45966 | U34: Friday | V34: FALSE | W34: FALSE | X34: Autumn | Y34: =IF(G34="No-show",1,IF(G34="Attended",0,"")) -> 1 | Z34: =IF(H34="","Unknown",IF(H34<=3,"0-3 days",IF(H34<=7,"4-7 days",IF(H34<=14,"8-14 days",IF(H34<=30,"15-30 days","31+ days"))))) -> 31+ days | AA34: =IF(M34="","Unknown",IF(M34<0.5,"Low",IF(M34<0.75,"Moderate",IF(M34<0.9,"Good","Very Good")))) -> Good | AB34: =IF(G34="Attended","Attended",IF(G34="No-show","No-show","Excluded")) -> No-show
A35: A00034 | B35: P0006 | C35: D009 | D35: 45922 | E35: 45877 | F35: Neurology | G35: No-show | H35: 45 | I35: 13:30 | J35: 60+ | K35: Urban | L35: 4 | M35: 0.47 | N35: Neurologist | O35: Mon-Fri PM | P35: 18 | R35: Not Required | S35: No Response | U35: Monday | V35: FALSE | W35: FALSE | X35: Autumn | Y35: =IF(G35="No-show",1,IF(G35="Attended",0,"")) -> 1 | Z35: =IF(H35="","Unknown",IF(H35<=3,"0-3 days",IF(H35<=7,"4-7 days",IF(H35<=14,"8-14 days",IF(H35<=30,"15-30 days","31+ days"))))) -> 31+ days | AA35: =IF(M35="","Unknown",IF(M35<0.5,"Low",IF(M35<0.75,"Moderate",IF(M35<0.9,"Good","Very Good")))) -> Low | AB35: =IF(G35="Attended","Attended",IF(G35="No-show","No-show","Excluded")) -> No-show
A36: A00035 | B36: P0057 | C36: D005 | D36: 45994 | E36: 45939 | F36: General Medicine | G36: No-show | H36: 55 | I36: 08:30 | J36: 30-44 | K36: Suburban | L36: 11 | M36: 0.8 | N36: General Physician | O36: Mon-Fri AM | P36: 12 | Q36: SMS | R36: Yes | S36: No Response | T36: 45992 | U36: Wednesday | V36: FALSE | W36: FALSE | X36: Winter | Y36: =IF(G36="No-show",1,IF(G36="Attended",0,"")) -> 1 | Z36: =IF(H36="","Unknown",IF(H36<=3,"0-3 days",IF(H36<=7,"4-7 days",IF(H36<=14,"8-14 days",IF(H36<=30,"15-30 days","31+ days"))))) -> 31+ days | AA36: =IF(M36="","Unknown",IF(M36<0.5,"Low",IF(M36<0.75,"Moderate",IF(M36<0.9,"Good","Very Good")))) -> Good | AB36: =IF(G36="Attended","Attended",IF(G36="No-show","No-show","Excluded")) -> No-show
A37: A00036 | B37: P0037 | C37: D005 | D37: 45918 | E37: 45885 | F37: General Medicine | G37: Attended | H37: 33 | I37: 08:30 | J37: 18-29 | K37: Urban | L37: 4 | M37: 0.68 | N37: General Physician | O37: Mon-Fri AM | P37: 12 | Q37: SMS | R37: Yes | S37: No Response | T37: 45916 | U37: Thursday | V37: FALSE | W37: FALSE | X37: Autumn | Y37: =IF(G37="No-show",1,IF(G37="Attended",0,"")) -> 0 | Z37: =IF(H37="","Unknown",IF(H37<=3,"0-3 days",IF(H37<=7,"4-7 days",IF(H37<=14,"8-14 days",IF(H37<=30,"15-30 days","31+ days"))))) -> 31+ days | AA37: =IF(M37="","Unknown",IF(M37<0.5,"Low",IF(M37<0.75,"Moderate",IF(M37<0.9,"Good","Very Good")))) -> Moderate | AB37: =IF(G37="Attended","Attended",IF(G37="No-show","No-show","Excluded")) -> Attended
A38: A00037 | B38: P0271 | C38: D017 | D38: 46014 | E38: 45958 | F38: ENT | G38: Attended | H38: 56 | I38: 14:00 | J38: 0-17 | K38: Urban | L38: 4 | M38: 0.95 | N38: ENT Specialist | O38: Mon-Fri PM | P38: 18 | Q38: SMS | R38: No | S38: Unknown | U38: Tuesday | V38: FALSE | W38: FALSE | X38: Winter | Y38: =IF(G38="No-show",1,IF(G38="Attended",0,"")) -> 0 | Z38: =IF(H38="","Unknown",IF(H38<=3,"0-3 days",IF(H38<=7,"4-7 days",IF(H38<=14,"8-14 days",IF(H38<=30,"15-30 days","31+ days"))))) -> 31+ days | AA38: =IF(M38="","Unknown",IF(M38<0.5,"Low",IF(M38<0.75,"Moderate",IF(M38<0.9,"Good","Very Good")))) -> Very Good | AB38: =IF(G38="Attended","Attended",IF(G38="No-show","No-show","Excluded")) -> Attended
A39: A00038 | B39: P0272 | C39: D009 | D39: 45919 | E39: 45874 | F39: Neurology | G39: No-show | H39: 45 | I39: 09:00 | J39: 18-29 | K39: Rural | L39: 7 | M39: 0.86 | N39: Neurologist | O39: Mon-Fri PM | P39: 18 | Q39: SMS | R39: Yes | S39: Cancelled | T39: 45918 | U39: Friday | V39: FALSE | W39: FALSE | X39: Autumn | Y39: =IF(G39="No-show",1,IF(G39="Attended",0,"")) -> 1 | Z39: =IF(H39="","Unknown",IF(H39<=3,"0-3 days",IF(H39<=7,"4-7 days",IF(H39<=14,"8-14 days",IF(H39<=30,"15-30 days","31+ days"))))) -> 31+ days | AA39: =IF(M39="","Unknown",IF(M39<0.5,"Low",IF(M39<0.75,"Moderate",IF(M39<0.9,"Good","Very Good")))) -> Good | AB39: =IF(G39="Attended","Attended",IF(G39="No-show","No-show","Excluded")) -> No-show
A40: A00039 | B40: P0471 | C40: D018 | D40: 45963 | E40: 45918 | F40: Neurology | G40: Attended | H40: 45 | I40: 08:30 | J40: 30-44 | K40: Suburban | L40: 2 | M40: 0.73 | N40: Neurologist | O40: Mon-Sat AM | P40: 15 | Q40: Email | R40: Yes | S40: No Response | T40: 45960 | U40: Sunday | V40: TRUE | W40: FALSE | X40: Autumn | Y40: =IF(G40="No-show",1,IF(G40="Attended",0,"")) -> 0 | Z40: =IF(H40="","Unknown",IF(H40<=3,"0-3 days",IF(H40<=7,"4-7 days",IF(H40<=14,"8-14 days",IF(H40<=30,"15-30 days","31+ days"))))) -> 31+ days | AA40: =IF(M40="","Unknown",IF(M40<0.5,"Low",IF(M40<0.75,"Moderate",IF(M40<0.9,"Good","Very Good")))) -> Moderate | AB40: =IF(G40="Attended","Attended",IF(G40="No-show","No-show","Excluded")) -> Attended
...
